Workbook

Sheet README
A1: Sinochem Holdings - sector peer comparison (Energy, Agriculture, Rubber)
A2: Prepared 12 Oct 2026. Basis: fiscal year ended 31 Dec 2025 (audited / filed), with H1 2026 momentum where available.
A4: How to read this workbook
A5: Scorecard - rank of each Sinochem entity against its peer group on nine headline metrics (live formulas).
A6: Energy / Agriculture / Rubber - full ratio matrices, peer median/high/low, sub-group medians, and anchor-minus-median row (green = better, red = worse).
A7: H1-2026 momentum - first-half 2026 vs first-half 2025 revenue and net income.
A8: Group context - disclosed Sinochem-level data (Sinochem Corp, Sinochem Energy segments, Syngenta Group, Pirelli).
A9: Data - standardised inputs (blue) with the FY2024 comparatives used for growth and averages; FX - editable USD translation rates.
A11: What 'Sinochem' means here
A12: Sinochem Holdings (中国中化控股) is a state-owned, unlisted group; it publishes no consolidated sector split. Each sector is therefore anchored on the group's operating entities that DO disclose full financials:
A13: Energy: Sinochem Energy (中化能源), the petrochemical segment's operating company (trading + 15 mt/y refining capacity centred on Quanzhou + retail).
A14: Agriculture: Syngenta AG (global crop protection + seeds) with ADAMA, Yangnong and Sinofert as additional group entities; Syngenta Group headline sales/EBITDA in 'Group context'.
... A30: 6) Interim read-through (H1 2026) is limited to companies that filed H1 reports; the 2026 oil-price spike materially lifts refining profits.

Sheet Scorecard
A1: Scorecard - where each Sinochem entity ranks against its peer group (FY2025)
A2: Rank 1 = best among the entity plus its peers (n shown). Tier: top third / mid / bottom third by rank. All values are live formulas pulling from the sector sheets. Syngenta AG, ADAMA and Yangnong are compared with crop-protection & seeds peers; Sinofert with crop-nutrition peers.
A4: Sinochem entity | B4: Peer group | C4: Metric | D4: Entity | E4: Peer median | F4: Entity - median | G4: Rank | H4: of n | I4: Tier
A5: Sinochem Energy (中化能源) | B5: All listed peers | C5: Revenue growth FY25 | D5: =Energy!F8 -> -0.076815097 | E5: =IFERROR(MEDIAN(Energy!F9:F13),"n/a") -> -0.094640798 | F5: =IFERROR(D5-E5,"n/a") -> 0.017825701 | G5: =IF(ISNUMBER(D5),1+COUNTIF(Energy!F9:F13,">"&D5),"n/a") -> 3 | H5: =IF(ISNUMBER(D5),1+COUNT(Energy!F9:F13),"n/a") -> 6 | I5: =IF(ISNUMBER(G5),IF((H5-G5)/(H5-1)>=0.67,"Top third",IF((H5-G5)/(H5-1)<=0.33,"Bottom third","Mid-pack")),IF(D5="n.m.","Bottom third (n.m.)","n/a")) -> Mid-pack
C6: EBITDA margin | D6: =Energy!J8 -> 0.012682565 | E6: =IFERROR(MEDIAN(Energy!J9:J13),"n/a") -> 0.085277705 | F6: =IFERROR(D6-E6,"n/a") -> -0.07259514 | G6: =IF(ISNUMBER(D6),1+COUNTIF(Energy!J9:J13,">"&D6),"n/a") -> 6 | H6: =IF(ISNUMBER(D6),1+COUNT(Energy!J9:J13),"n/a") -> 6 | I6: =IF(ISNUMBER(G6),IF((H6-G6)/(H6-1)>=0.67,"Top third",IF((H6-G6)/(H6-1)<=0.33,"Bottom third","Mid-pack")),IF(D6="n.m.","Bottom third (n.m.)","n/a")) -> Bottom third
C7: Net margin | D7: =Energy!L8 -> -0.0042697433 | E7: =IFERROR(MEDIAN(Energy!L9:L13),"n/a") -> 0.012663535 | F7: =IFERROR(D7-E7,"n/a") -> -0.016933278 | G7: =IF(ISNUMBER(D7),1+COUNTIF(Energy!L9:L13,">"&D7),"n/a") -> 5 | H7: =IF(ISNUMBER(D7),1+COUNT(Energy!L9:L13),"n/a") -> 6 | I7: =IF(ISNUMBER(G7),IF((H7-G7)/(H7-1)>=0.67,"Top third",IF((H7-G7)/(H7-1)<=0.33,"Bottom third","Mid-pack")),IF(D7="n.m.","Bottom third (n.m.)","n/a")) -> Bottom third
C8: ROE (NI / avg equity) | D8: =Energy!N8 -> -0.045469204 | E8: =IFERROR(MEDIAN(Energy!N9:N13),"n/a") -> 0.035858428 | F8: =IFERROR(D8-E8,"n/a") -> -0.081327632 | G8: =IF(ISNUMBER(D8),1+COUNTIF(Energy!N9:N13,">"&D8),"n/a") -> 5 | H8: =IF(ISNUMBER(D8),1+COUNT(Energy!N9:N13),"n/a") -> 6 | I8: =IF(ISNUMBER(G8),IF((H8-G8)/(H8-1)>=0.67,"Top third",IF((H8-G8)/(H8-1)<=0.33,"Bottom third","Mid-pack")),IF(D8="n.m.","Bottom third (n.m.)","n/a")) -> Bottom third
C9: EBITDA / avg assets | D9: =Energy!M8 -> 0.048118216 | E9: =IFERROR(MEDIAN(Energy!M9:M13),"n/a") -> 0.080882693 | F9: =IFERROR(D9-E9,"n/a") -> -0.032764477 | G9: =IF(ISNUMBER(D9),1+COUNTIF(Energy!M9:M13,">"&D9),"n/a") -> 6 | H9: =IF(ISNUMBER(D9),1+COUNT(Energy!M9:M13),"n/a") -> 6 | I9: =IF(ISNUMBER(G9),IF((H9-G9)/(H9-1)>=0.67,"Top third",IF((H9-G9)/(H9-1)<=0.33,"Bottom third","Mid-pack")),IF(D9="n.m.","Bottom third (n.m.)","n/a")) -> Bottom third
C10: Net debt / EBITDA (x) | D10: =Energy!S8 -> 4.4530793 | E10: =IFERROR(MEDIAN(Energy!S9:S13),"n/a") -> 2.2180399 | F10: =IFERROR(D10-E10,"n/a") -> 2.2350395 | G10: =IF(ISNUMBER(D10),1+COUNTIF(Energy!S9:S13,"<"&D10),"n/a") -> 4 | H10: =IF(ISNUMBER(D10),1+COUNT(Energy!S9:S13),"n/a") -> 6 | I10: =IF(ISNUMBER(G10),IF((H10-G10)/(H10-1)>=0.67,"Top third",IF((H10-G10)/(H10-1)<=0.33,"Bottom third","Mid-pack")),IF(D10="n.m.","Bottom third (n.m.)","n/a")) -> Mid-pack
C11: Interest cover (EBIT / interest, x) | D11: =Energy!T8 -> -0.38309722 | E11: =IFERROR(MEDIAN(Energy!T9:T13),"n/a") -> 2.8640308 | F11: =IFERROR(D11-E11,"n/a") -> -3.247128 | G11: =IF(ISNUMBER(D11),1+COUNTIF(Energy!T9:T13,">"&D11),"n/a") -> 5 | H11: =IF(ISNUMBER(D11),1+COUNT(Energy!T9:T13),"n/a") -> 6 | I11: =IF(ISNUMBER(G11),IF((H11-G11)/(H11-1)>=0.67,"Top third",IF((H11-G11)/(H11-1)<=0.33,"Bottom third","Mid-pack")),IF(D11="n.m.","Bottom third (n.m.)","n/a")) -> Bottom third
C12: OCF / EBITDA (cash conversion) | D12: =Energy!W8 -> 1.3367685 | E12: =IFERROR(MEDIAN(Energy!W9:W13),"n/a") -> 0.94757037 | F12: =IFERROR(D12-E12,"n/a") -> 0.38919811 | G12: =IF(ISNUMBER(D12),1+COUNTIF(Energy!W9:W13,">"&D12),"n/a") -> 2 | H12: =IF(ISNUMBER(D12),1+COUNT(Energy!W9:W13),"n/a") -> 6 | I12: =IF(ISNUMBER(G12),IF((H12-G12)/(H12-1)>=0.67,"Top third",IF((H12-G12)/(H12-1)<=0.33,"Bottom third","Mid-pack")),IF(D12="n.m.","Bottom third (n.m.)","n/a")) -> Top third
C13: FCF margin | D13: =Energy!Y8 -> 0.013079256 | E13: =IFERROR(MEDIAN(Energy!Y9:Y13),"n/a") -> 0.010371884 | F13: =IFERROR(D13-E13,"n/a") -> 0.0027073719 | G13: =IF(ISNUMBER(D13),1+COUNTIF(Energy!Y9:Y13,">"&D13),"n/a") -> 3 | H13: =IF(ISNUMBER(D13),1+COUNT(Energy!Y9:Y13),"n/a") -> 6 | I13: =IF(ISNUMBER(G13),IF((H13-G13)/(H13-1)>=0.67,"Top third",IF((H13-G13)/(H13-1)<=0.33,"Bottom third","Mid-pack")),IF(D13="n.m.","Bottom third (n.m.)","n/a")) -> Mid-pack
A14: Syngenta AG (global CP + Seeds) | B14: Crop-protection & seeds peers | C14: Revenue growth FY25 | D14: =Agriculture!F8 -> 0.0010600082 | E14: =IFERROR(MEDIAN(Agriculture!F12:F15),"n/a") -> 0.049982705 | F14: =IFERROR(D14-E14,"n/a") -> -0.048922696 | G14: =IF(ISNUMBER(D14),1+COUNTIF(Agriculture!F12:F15,">"&D14),"n/a") -> 4 | H14: =IF(ISNUMBER(D14),1+COUNT(Agriculture!F12:F15),"n/a") -> 5 | I14: =IF(ISNUMBER(G14),IF((H14-G14)/(H14-1)>=0.67,"Top third",IF((H14-G14)/(H14-1)<=0.33,"Bottom third","Mid-pack")),IF(D14="n.m.","Bottom third (n.m.)","n/a")) -> Bottom third
C15: EBITDA margin | D15: =Agriculture!I8 -> 0.12394847 | E15: =IFERROR(MEDIAN(Agriculture!I12:I15),"n/a") -> 0.1675157 | F15: =IFERROR(D15-E15,"n/a") -> -0.043567232 | G15: =IF(ISNUMBER(D15),1+COUNTIF(Agriculture!I12:I15,">"&D15),"n/a") -> 4 | H15: =IF(ISNUMBER(D15),1+COUNT(Agriculture!I12:I15),"n/a") -> 5 | I15: =IF(ISNUMBER(G15),IF((H15-G15)/(H15-1)>=0.67,"Top third",IF((H15-G15)/(H15-1)<=0.33,"Bottom third","Mid-pack")),IF(D15="n.m.","Bottom third (n.m.)","n/a")) -> Bottom third
C16: Net margin | D16: =Agriculture!K8 -> -0.0089417025 | E16: =IFERROR(MEDIAN(Agriculture!K12:K15),"n/a") -> 0.063985222 | F16: =IFERROR(D16-E16,"n/a") -> -0.072926924 | G16: =IF(ISNUMBER(D16),1+COUNTIF(Agriculture!K12:K15,">"&D16),"n/a") -> 4 | H16: =IF(ISNUMBER(D16),1+COUNT(Agriculture!K12:K15),"n/a") -> 5 | I16: =IF(ISNUMBER(G16),IF((H16-G16)/(H16-1)>=0.67,"Top third",IF((H16-G16)/(H16-1)<=0.33,"Bottom third","Mid-pack")),IF(D16="n.m.","Bottom third (n.m.)","n/a")) -> Bottom third
C17: ROE (NI / avg equity) | D17: =Agriculture!M8 -> -0.020753687 | E17: =IFERROR(MEDIAN(Agriculture!M12:M15),"n/a") -> 0.054616975 | F17: =IFERROR(D17-E17,"n/a") -> -0.075370661 | G17: =IF(ISNUMBER(D17),1+COUNTIF(Agriculture!M12:M15,">"&D17),"n/a") -> 4 | H17: =IF(ISNUMBER(D17),1+COUNT(Agriculture!M12:M15),"n/a") -> 5 | I17: =IF(ISNUMBER(G17),IF((H17-G17)/(H17-1)>=0.67,"Top third",IF((H17-G17)/(H17-1)<=0.33,"Bottom third","Mid-pack")),IF(D17="n.m.","Bottom third (n.m.)","n/a")) -> Bottom third
C18: EBITDA / avg assets | D18: =Agriculture!L8 -> 0.069948875 | E18: =IFERROR(MEDIAN(Agriculture!L12:L15),"n/a") -> 0.086919213 | F18: =IFERROR(D18-E18,"n/a") -> -0.016970338 | G18: =IF(ISNUMBER(D18),1+COUNTIF(Agriculture!L12:L15,">"&D18),"n/a") -> 4 | H18: =IF(ISNUMBER(D18),1+COUNT(Agriculture!L12:L15),"n/a") -> 5 | I18: =IF(ISNUMBER(G18),IF((H18-G18)/(H18-1)>=0.67,"Top third",IF((H18-G18)/(H18-1)<=0.33,"Bottom third","Mid-pack")),IF(D18="n.m.","Bottom third (n.m.)","n/a")) -> Bottom third
C19: Net debt / EBITDA (x) | D19: =Agriculture!R8 -> 4.6767916 | E19: =IFERROR(MEDIAN(Agriculture!R12:R15),"n/a") -> 1.3321827 | F19: =IFERROR(D19-E19,"n/a") -> 3.344609 | G19: =IF(ISNUMBER(D19),1+COUNTIF(Agriculture!R12:R15,"<"&D19),"n/a") -> 4 | H19: =IF(ISNUMBER(D19),1+COUNT(Agriculture!R12:R15),"n/a") -> 4 | I19: =IF(ISNUMBER(G19),IF((H19-G19)/(H19-1)>=0.67,"Top third",IF((H19-G19)/(H19-1)<=0.33,"Bottom third","Mid-pack")),IF(D19="n.m.","Bottom third (n.m.)","n/a")) -> Bottom third
C20: Interest cover (EBIT / interest, x) | D20: =Agriculture!S8 -> 1.5878553 | E20: =IFERROR(MEDIAN(Agriculture!S12:S15),"n/a") -> 9.9984965 | F20: =IFERROR(D20-E20,"n/a") -> -8.4106412 | G20: =IF(ISNUMBER(D20),1+COUNTIF(Agriculture!S12:S15,">"&D20),"n/a") -> 4 | H20: =IF(ISNUMBER(D20),1+COUNT(Agriculture!S12:S15),"n/a") -> 5 | I20: =IF(ISNUMBER(G20),IF((H20-G20)/(H20-1)>=0.67,"Top third",IF((H20-G20)/(H20-1)<=0.33,"Bottom third","Mid-pack")),IF(D20="n.m.","Bottom third (n.m.)","n/a")) -> Bottom third
C21: OCF / EBITDA (cash conversion) | D21: =Agriculture!V8 -> 0.72425249 | E21: =IFERROR(MEDIAN(Agriculture!V12:V15),"n/a") -> 0.72113505 | F21: =IFERROR(D21-E21,"n/a") -> 0.0031174422 | G21: =IF(ISNUMBER(D21),1+COUNTIF(Agriculture!V12:V15,">"&D21),"n/a") -> 2 | H21: =IF(ISNUMBER(D21),1+COUNT(Agriculture!V12:V15),"n/a") -> 4 | I21: =IF(ISNUMBER(G21),IF((H21-G21)/(H21-1)>=0.67,"Top third",IF((H21-G21)/(H21-1)<=0.33,"Bottom third","Mid-pack")),IF(D21="n.m.","Bottom third (n.m.)","n/a")) -> Mid-pack
C22: FCF margin | D22: =Agriculture!X8 -> 0.01817754 | E22: =IFERROR(MEDIAN(Agriculture!X12:X15),"n/a") -> -0.0029318466 | F22: =IFERROR(D22-E22,"n/a") -> 0.021109386 | G22: =IF(ISNUMBER(D22),1+COUNTIF(Agriculture!X12:X15,">"&D22),"n/a") -> 3 | H22: =IF(ISNUMBER(D22),1+COUNT(Agriculture!X12:X15),"n/a") -> 5 | I22: =IF(ISNUMBER(G22),IF((H22-G22)/(H22-1)>=0.67,"Top third",IF((H22-G22)/(H22-1)<=0.33,"Bottom third","Mid-pack")),IF(D22="n.m.","Bottom third (n.m.)","n/a")) -> Mid-pack
A23: ADAMA | B23: Crop-protection & seeds peers | C23: Revenue growth FY25 | D23: =Agriculture!F9 -> -0.018429841 | E23: =IFERROR(MEDIAN(Agriculture!F12:F15),"n/a") -> 0.049982705 | F23: =IFERROR(D23-E23,"n/a") -> -0.068412546 | G23: =IF(ISNUMBER(D23),1+COUNTIF(Agriculture!F12:F15,">"&D23),"n/a") -> 4 | H23: =IF(ISNUMBER(D23),1+COUNT(Agriculture!F12:F15),"n/a") -> 5 | I23: =IF(ISNUMBER(G23),IF((H23-G23)/(H23-1)>=0.67,"Top third",IF((H23-G23)/(H23-1)<=0.33,"Bottom third","Mid-pack")),IF(D23="n.m.","Bottom third (n.m.)","n/a")) -> Bottom third
C24: EBITDA margin | D24: =Agriculture!I9 -> 0.11881538 | E24: =IFERROR(MEDIAN(Agriculture!I12:I15),"n/a") -> 0.1675157 | F24: =IFERROR(D24-E24,"n/a") -> -0.048700319 | G24: =IF(ISNUMBER(D24),1+COUNTIF(Agriculture!I12:I15,">"&D24),"n/a") -> 4 | H24: =IF(ISNUMBER(D24),1+COUNT(Agriculture!I12:I15),"n/a") -> 5 | I24: =IF(ISNUMBER(G24),IF((H24-G24)/(H24-1)>=0.67,"Top third",IF((H24-G24)/(H24-1)<=0.33,"Bottom third","Mid-pack")),IF(D24="n.m.","Bottom third (n.m.)","n/a")) -> Bottom third
C25: Net margin | D25: =Agriculture!K9 -> -0.036128311 | E25: =IFERROR(MEDIAN(Agriculture!K12:K15),"n/a") -> 0.063985222 | F25: =IFERROR(D25-E25,"n/a") -> -0.10011353 | G25: =IF(ISNUMBER(D25),1+COUNTIF(Agriculture!K12:K15,">"&D25),"n/a") -> 4 | H25: =IF(ISNUMBER(D25),1+COUNT(Agriculture!K12:K15),"n/a") -> 5 | I25: =IF(ISNUMBER(G25),IF((H25-G25)/(H25-1)>=0.67,"Top third",IF((H25-G25)/(H25-1)<=0.33,"Bottom third","Mid-pack")),IF(D25="n.m.","Bottom third (n.m.)","n/a")) -> Bottom third
C26: ROE (NI / avg equity) | D26: =Agriculture!M9 -> -0.057195435 | E26: =IFERROR(MEDIAN(Agriculture!M12:M15),"n/a") -> 0.054616975 | F26: =IFERROR(D26-E26,"n/a") -> -0.11181241 | G26: =IF(ISNUMBER(D26),1+COUNTIF(Agriculture!M12:M15,">"&D26),"n/a") -> 4 | H26: =IF(ISNUMBER(D26),1+COUNT(Agriculture!M12:M15),"n/a") -> 5 | I26: =IF(ISNUMBER(G26),IF((H26-G26)/(H26-1)>=0.67,"Top third",IF((H26-G26)/(H26-1)<=0.33,"Bottom third","Mid-pack")),IF(D26="n.m.","Bottom third (n.m.)","n/a")) -> Bottom third
C27: EBITDA / avg assets | D27: =Agriculture!L9 -> 0.069811845 | E27: =IFERROR(MEDIAN(Agriculture!L12:L15),"n/a") -> 0.086919213 | F27: =IFERROR(D27-E27,"n/a") -> -0.017107368 | G27: =IF(ISNUMBER(D27),1+COUNTIF(Agriculture!L12:L15,">"&D27),"n/a") -> 4 | H27: =IF(ISNUMBER(D27),1+COUNT(Agriculture!L12:L15),"n/a") -> 5 | I27: =IF(ISNUMBER(G27),IF((H27-G27)/(H27-1)>=0.67,"Top third",IF((H27-G27)/(H27-1)<=0.33,"Bottom third","Mid-pack")),IF(D27="n.m.","Bottom third (n.m.)","n/a")) -> Bottom third
C28: Net debt / EBITDA (x) | D28: =Agriculture!R9 -> 4.1294722 | E28: =IFERROR(MEDIAN(Agriculture!R12:R15),"n/a") -> 1.3321827 | F28: =IFERROR(D28-E28,"n/a") -> 2.7972896 | G28: =IF(ISNUMBER(D28),1+COUNTIF(Agriculture!R12:R15,"<"&D28),"n/a") -> 4 | H28: =IF(ISNUMBER(D28),1+COUNT(Agriculture!R12:R15),"n/a") -> 4 | I28: =IF(ISNUMBER(G28),IF((H28-G28)/(H28-1)>=0.67,"Top third",IF((H28-G28)/(H28-1)<=0.33,"Bottom third","Mid-pack")),IF(D28="n.m.","Bottom third (n.m.)","n/a")) -> Bottom third
C29: Interest cover (EBIT / interest, x) | D29: =Agriculture!S9 -> 1.3074426 | E29: =IFERROR(MEDIAN(Agriculture!S12:S15),"n/a") -> 9.9984965 | F29: =IFERROR(D29-E29,"n/a") -> -8.691054 | G29: =IF(ISNUMBER(D29),1+COUNTIF(Agriculture!S12:S15,">"&D29),"n/a") -> 4 | H29: =IF(ISNUMBER(D29),1+COUNT(Agriculture!S12:S15),"n/a") -> 5 | I29: =IF(ISNUMBER(G29),IF((H29-G29)/(H29-1)>=0.67,"Top third",IF((H29-G29)/(H29-1)<=0.33,"Bottom third","Mid-pack")),IF(D29="n.m.","Bottom third (n.m.)","n/a")) -> Bottom third
C30: OCF / EBITDA (cash conversion) | D30: =Agriculture!V9 -> 1.1772667 | E30: =IFERROR(MEDIAN(Agriculture!V12:V15),"n/a") -> 0.72113505 | F30: =IFERROR(D30-E30,"n/a") -> 0.4561316 | G30: =IF(ISNUMBER(D30),1+COUNTIF(Agriculture!V12:V15,">"&D30),"n/a") -> 1 | H30: =IF(ISNUMBER(D30),1+COUNT(Agriculture!V12:V15),"n/a") -> 4 | I30: =IF(ISNUMBER(G30),IF((H30-G30)/(H30-1)>=0.67,"Top third",IF((H30-G30)/(H30-1)<=0.33,"Bottom third","Mid-pack")),IF(D30="n.m.","Bottom third (n.m.)","n/a")) -> Top third
C31: FCF margin | D31: =Agriculture!X9 -> 0.097946918 | E31: =IFERROR(MEDIAN(Agriculture!X12:X15),"n/a") -> -0.0029318466 | F31: =IFERROR(D31-E31,"n/a") -> 0.10087876 | G31: =IF(ISNUMBER(D31),1+COUNTIF(Agriculture!X12:X15,">"&D31),"n/a") -> 2 | H31: =IF(ISNUMBER(D31),1+COUNT(Agriculture!X12:X15),"n/a") -> 5 | I31: =IF(ISNUMBER(G31),IF((H31-G31)/(H31-1)>=0.67,"Top third",IF((H31-G31)/(H31-1)<=0.33,"Bottom third","Mid-pack")),IF(D31="n.m.","Bottom third (n.m.)","n/a")) -> Top third
A32: Yangnong Chemical | B32: Crop-protection & seeds peers | C32: Revenue growth FY25 | D32: =Agriculture!F10 -> 0.13758373 | E32: =IFERROR(MEDIAN(Agriculture!F12:F15),"n/a") -> 0.049982705 | F32: =IFERROR(D32-E32,"n/a") -> 0.087601026 | G32: =IF(ISNUMBER(D32),1+COUNTIF(Agriculture!F12:F15,">"&D32),"n/a") -> 2 | H32: =IF(ISNUMBER(D32),1+COUNT(Agriculture!F12:F15),"n/a") -> 5 | I32: =IF(ISNUMBER(G32),IF((H32-G32)/(H32-1)>=0.67,"Top third",IF((H32-G32)/(H32-1)<=0.33,"Bottom third","Mid-pack")),IF(D32="n.m.","Bottom third (n.m.)","n/a")) -> Top third
C33: EBITDA margin | D33: =Agriculture!I10 -> 0.25800367 | E33: =IFERROR(MEDIAN(Agriculture!I12:I15),"n/a") -> 0.1675157 | F33: =IFERROR(D33-E33,"n/a") -> 0.090487971 | G33: =IF(ISNUMBER(D33),1+COUNTIF(Agriculture!I12:I15,">"&D33),"n/a") -> 1 | H33: =IF(ISNUMBER(D33),1+COUNT(Agriculture!I12:I15),"n/a") -> 5 | I33: =IF(ISNUMBER(G33),IF((H33-G33)/(H33-1)>=0.67,"Top third",IF((H33-G33)/(H33-1)<=0.33,"Bottom third","Mid-pack")),IF(D33="n.m.","Bottom third (n.m.)","n/a")) -> Top third
C34: Net margin | D34: =Agriculture!K10 -> 0.10838565 | E34: =IFERROR(MEDIAN(Agriculture!K12:K15),"n/a") -> 0.063985222 | F34: =IFERROR(D34-E34,"n/a") -> 0.044400424 | G34: =IF(ISNUMBER(D34),1+COUNTIF(Agriculture!K12:K15,">"&D34),"n/a") -> 1 | H34: =IF(ISNUMBER(D34),1+COUNT(Agriculture!K12:K15),"n/a") -> 5 | I34: =IF(ISNUMBER(G34),IF((H34-G34)/(H34-1)>=0.67,"Top third",IF((H34-G34)/(H34-1)<=0.33,"Bottom third","Mid-pack")),IF(D34="n.m.","Bottom third (n.m.)","n/a")) -> Top third
C35: ROE (NI / avg equity) | D35: =Agriculture!M10 -> 0.1168737 | E35: =IFERROR(MEDIAN(Agriculture!M12:M15),"n/a") -> 0.054616975 | F35: =IFERROR(D35-E35,"n/a") -> 0.062256728 | G35: =IF(ISNUMBER(D35),1+COUNTIF(Agriculture!M12:M15,">"&D35),"n/a") -> 2 | H35: =IF(ISNUMBER(D35),1+COUNT(Agriculture!M12:M15),"n/a") -> 5 | I35: =IF(ISNUMBER(G35),IF((H35-G35)/(H35-1)>=0.67,"Top third",IF((H35-G35)/(H35-1)<=0.33,"Bottom third","Mid-pack")),IF(D35="n.m.","Bottom third (n.m.)","n/a")) -> Top third
C36: EBITDA / avg assets | D36: =Agriculture!L10 -> 0.17085077 | E36: =IFERROR(MEDIAN(Agriculture!L12:L15),"n/a") -> 0.086919213 | F36: =IFERROR(D36-E36,"n/a") -> 0.083931556 | G36: =IF(ISNUMBER(D36),1+COUNTIF(Agriculture!L12:L15,">"&D36),"n/a") -> 1 | H36: =IF(ISNUMBER(D36),1+COUNT(Agriculture!L12:L15),"n/a") -> 5 | I36: =IF(ISNUMBER(G36),IF((H36-G36)/(H36-1)>=0.67,"Top third",IF((H36-G36)/(H36-1)<=0.33,"Bottom third","Mid-pack")),IF(D36="n.m.","Bottom third (n.m.)","n/a")) -> Top third
C37: Net debt / EBITDA (x) | D37: =Agriculture!R10 -> -0.13738427 | E37: =IFERROR(MEDIAN(Agriculture!R12:R15),"n/a") -> 1.3321827 | F37: =IFERROR(D37-E37,"n/a") -> -1.4695669 | G37: =IF(ISNUMBER(D37),1+COUNTIF(Agriculture!R12:R15,"<"&D37),"n/a") -> 2 | H37: =IF(ISNUMBER(D37),1+COUNT(Agriculture!R12:R15),"n/a") -> 4 | I37: =IF(ISNUMBER(G37),IF((H37-G37)/(H37-1)>=0.67,"Top third",IF((H37-G37)/(H37-1)<=0.33,"Bottom third","Mid-pack")),IF(D37="n.m.","Bottom third (n.m.)","n/a")) -> Mid-pack
C38: Interest cover (EBIT / interest, x) | D38: =Agriculture!S10 -> 35.282383 | E38: =IFERROR(MEDIAN(Agriculture!S12:S15),"n/a") -> 9.9984965 | F38: =IFERROR(D38-E38,"n/a") -> 25.283887 | G38: =IF(ISNUMBER(D38),1+COUNTIF(Agriculture!S12:S15,">"&D38),"n/a") -> 1 | H38: =IF(ISNUMBER(D38),1+COUNT(Agriculture!S12:S15),"n/a") -> 5 | I38: =IF(ISNUMBER(G38),IF((H38-G38)/(H38-1)>=0.67,"Top third",IF((H38-G38)/(H38-1)<=0.33,"Bottom third","Mid-pack")),IF(D38="n.m.","Bottom third (n.m.)","n/a")) -> Top third
C39: OCF / EBITDA (cash conversion) | D39: =Agriculture!V10 -> 0.72380293 | E39: =IFERROR(MEDIAN(Agriculture!V12:V15),"n/a") -> 0.72113505 | F39: =IFERROR(D39-E39,"n/a") -> 0.0026678849 | G39: =IF(ISNUMBER(D39),1+COUNTIF(Agriculture!V12:V15,">"&D39),"n/a") -> 2 | H39: =IF(ISNUMBER(D39),1+COUNT(Agriculture!V12:V15),"n/a") -> 4 | I39: =IF(ISNUMBER(G39),IF((H39-G39)/(H39-1)>=0.67,"Top third",IF((H39-G39)/(H39-1)<=0.33,"Bottom third","Mid-pack")),IF(D39="n.m.","Bottom third (n.m.)","n/a")) -> Mid-pack
C40: FCF margin | D40: =Agriculture!X10 -> 0.1057587 | E40: =IFERROR(MEDIAN(Agriculture!X12:X15),"n/a") -> -0.0029318466 | F40: =IFERROR(D40-E40,"n/a") -> 0.10869054 | G40: =IF(ISNUMBER(D40),1+COUNTIF(Agriculture!X12:X15,">"&D40),"n/a") -> 2 | H40: =IF(ISNUMBER(D40),1+COUNT(Agriculture!X12:X15),"n/a") -> 5 | I40: =IF(ISNUMBER(G40),IF((H40-G40)/(H40-1)>=0.67,"Top third",IF((H40-G40)/(H40-1)<=0.33,"Bottom third","Mid-pack")),IF(D40="n.m.","Bottom third (n.m.)","n/a")) -> Top third
A41: Sinofert | B41: Crop-nutrition peers | C41: Revenue growth FY25 | D41: =Agriculture!F11 -> 0.093969655 | E41: =IFERROR(MEDIAN(Agriculture!F16:F19),"n/a") -> 0.029705638 | F41: =IFERROR(D41-E41,"n/a") -> 0.064264017 | G41: =IF(ISNUMBER(D41),1+COUNTIF(Agriculture!F16:F19,">"&D41),"n/a") -> 1 | H41: =IF(ISNUMBER(D41),1+COUNT(Agriculture!F16:F19),"n/a") -> 5 | I41: =IF(ISNUMBER(G41),IF((H41-G41)/(H41-1)>=0.67,"Top third",IF((H41-G41)/(H41-1)<=0.33,"Bottom third","Mid-pack")),IF(D41="n.m.","Bottom third (n.m.)","n/a")) -> Top third
...

Sheet Energy
A1: Energy - Sinochem Energy vs listed refining / petrochemical peers
A2: Sinochem Energy (中化能源) is the operating arm of Sinochem Corp's petrochemical segment: crude/product trading, 15 mt/y of refining capacity centred on Quanzhou, and fuel retail. FY2025 audited statements.
A3: FY2025, ratios computed from the 'Data' sheet. Amber rows = Sinochem Holdings group entities. Peer statistics exclude Sinochem entities. 'n.m.' = not meaningful (negative EBITDA); 'n/a' = not available.
D5: Scale | F5: Growth | H5: Profitability | M5: Returns | Q5: Leverage & liquidity | V5: Cash generation
A6: Entity | B6: Group | C6: Ccy | D6: Revenue (USD bn) | E6: Total assets (USD bn) | F6: Revenue growth FY25 | G6: EBITDA growth FY25 | H6: Gross margin | I6: Gross margin after taxes & surcharges | J6: EBITDA margin | K6: EBIT margin | L6: Net margin | M6: EBITDA / avg assets | N6: ROE (NI / avg equity) | O6: ROA (NI / avg assets) | P6: Asset turnover (x) | Q6: Liabilities / assets | R6: Debt / equity | S6: Net debt / EBITDA (x) | T6: Interest cover (EBIT / interest, x) | U6: Current ratio (x) | V6: OCF / revenue | W6: OCF / EBITDA (cash conversion) | X6: Capex / revenue | Y6: FCF margin | Z6: Free cash flow (USD bn)
A7: Direction (+1 higher is better, -1 lower is better, 0 informational) | D7: 0 | E7: 0 | F7: 1 | G7: 1 | H7: 1 | I7: 1 | J7: 1 | K7: 1 | L7: 1 | M7: 1 | N7: 1 | O7: 1 | P7: 1 | Q7: -1 | R7: -1 | S7: -1 | T7: 1 | U7: 1 | V7: 1 | W7: 1 | X7: 0 | Y7: 1 | Z7: 1
A8: Sinochem Energy (中化能源) | B8: Sinochem | C8: CNY | D8: =Data!$I$5/Data!$H$5/1000 -> 55.282696 | E8: =Data!$S$5/Data!$H$5/1000 -> 14.789913 | F8: =IFERROR(Data!$I$5/Data!$AD$5-1,"n/a") -> -0.076815097 | G8: =IFERROR(IF(Data!$AI$5<=0,"n.m.",Data!$N$5/Data!$AI$5-1),"n/a") -> 0.56502699 | H8: =IF(Data!$K$5="","n/a",Data!$K$5/Data!$I$5) -> 0.015979637 | I8: =IF(OR(Data!$K$5="",Data!$AC$5=""),"n/a",(Data!$K$5-Data!$AC$5)/Data!$I$5) -> 0.006840394 | J8: =IFERROR(Data!$N$5/Data!$I$5,"n/a") -> 0.012682565 | K8: =IFERROR(Data!$L$5/Data!$I$5,"n/a") -> -0.0010559733 | L8: =IFERROR(Data!$Q$5/Data!$I$5,"n/a") -> -0.0042697433 | M8: =IFERROR(Data!$N$5/AVERAGE(Data!$S$5,Data!$AN$5),"n/a") -> 0.048118216 | N8: =IFERROR(Data!$Q$5/AVERAGE(Data!$U$5,Data!$AP$5),"n/a") -> -0.045469204 | O8: =IFERROR(Data!$Q$5/AVERAGE(Data!$S$5,Data!$AN$5),"n/a") -> -0.016199596 | P8: =IFERROR(Data!$I$5/AVERAGE(Data!$S$5,Data!$AN$5),"n/a") -> 3.7940445 | Q8: =IFERROR(Data!$T$5/Data!$S$5,"n/a") -> 0.64970448 | R8: =IFERROR(Data!$Z$5/Data!$U$5,"n/a") -> 0.76157551 | S8: =IFERROR(IF(Data!$N$5<=0,"n.m.",(Data!$Z$5-Data!$W$5)/Data!$N$5),"n/a") -> 4.4530793 | T8: =IFERROR(IF(Data!$O$5<=0,"n/a",Data!$L$5/Data!$O$5),"n/a") -> -0.38309722 | U8: =IFERROR(Data!$X$5/Data!$Y$5,"n/a") -> 0.91231947 | V8: =IFERROR(Data!$AA$5/Data!$I$5,"n/a") -> 0.016953653 | W8: =IFERROR(IF(Data!$N$5<=0,"n.m.",Data!$AA$5/Data!$N$5),"n/a") -> 1.3367685 | X8: =IFERROR(Data!$AB$5/Data!$I$5,"n/a") -> 0.0038743972 | Y8: =IFERROR((Data!$AA$5-Data!$AB$5)/Data!$I$5,"n/a") -> 0.013079256 | Z8: =(Data!$AA$5-Data!$AB$5)/Data!$H$5/1000 -> 0.72305653
A9: Sinopec Corp | B9: State-owned major | C9: CNY | D9: =Data!$I$6/Data!$H$6/1000 -> 390.45911 | E9: =Data!$S$6/Data!$H$6/1000 -> 302.37298 | F9: =IFERROR(Data!$I$6/Data!$AD$6-1,"n/a") -> -0.094640798 | G9: =IFERROR(IF(Data!$AI$6<=0,"n.m.",Data!$N$6/Data!$AI$6-1),"n/a") -> -0.11455848 | H9: =IF(Data!$K$6="","n/a",Data!$K$6/Data!$I$6) -> 0.15886 | I9: =IF(OR(Data!$K$6="",Data!$AC$6=""),"n/a",(Data!$K$6-Data!$AC$6)/Data!$I$6) -> 0.068172927 | J9: =IFERROR(Data!$N$6/Data!$I$6,"n/a") -> 0.06160657 | K9: =IFERROR(Data!$L$6/Data!$I$6,"n/a") -> 0.019803254 | L9: =IFERROR(Data!$Q$6/Data!$I$6,"n/a") -> 0.012663535 | M9: =IFERROR(Data!$N$6/AVERAGE(Data!$S$6,Data!$AN$6),"n/a") -> 0.080882693 | N9: =IFERROR(Data!$Q$6/AVERAGE(Data!$U$6,Data!$AP$6),"n/a") -> 0.035858428 | O9: =IFERROR(Data!$Q$6/AVERAGE(Data!$S$6,Data!$AN$6),"n/a") -> 0.016625837 | P9: =IFERROR(Data!$I$6/AVERAGE(Data!$S$6,Data!$AN$6),"n/a") -> 1.3128907 | Q9: =IFERROR(Data!$T$6/Data!$S$6,"n/a") -> 0.54084051 | R9: =IFERROR(Data!$Z$6/Data!$U$6,"n/a") -> 0.53818758 | S9: =IFERROR(IF(Data!$N$6<=0,"n.m.",(Data!$Z$6-Data!$W$6)/Data!$N$6),"n/a") -> 2.2180399 | T9: =IFERROR(IF(Data!$O$6<=0,"n/a",Data!$L$6/Data!$O$6),"n/a") -> 2.8640308 | U9: =IFERROR(Data!$X$6/Data!$Y$6,"n/a") -> 0.74831974 | V9: =IFERROR(Data!$AA$6/Data!$I$6,"n/a") -> 0.05837656 | W9: =IFERROR(IF(Data!$N$6<=0,"n.m.",Data!$AA$6/Data!$N$6),"n/a") -> 0.94757037 | X9: =IFERROR(Data!$AB$6/Data!$I$6,"n/a") -> 0.048004676 | Y9: =IFERROR((Data!$AA$6-Data!$AB$6)/Data!$I$6,"n/a") -> 0.010371884 | Z9: =(Data!$AA$6-Data!$AB$6)/Data!$H$6/1000 -> 4.0497966
A10: PetroChina | B10: State-owned major | C10: CNY | D10: =Data!$I$7/Data!$H$7/1000 -> 401.80516 | E10: =Data!$S$7/Data!$H$7/1000 -> 401.66335 | F10: =IFERROR(Data!$I$7/Data!$AD$7-1,"n/a") -> -0.025021265 | G10: =IFERROR(IF(Data!$AI$7<=0,"n.m.",Data!$N$7/Data!$AI$7-1),"n/a") -> -0.029907707 | H10: =IF(Data!$K$7="","n/a",Data!$K$7/Data!$I$7) -> 0.21586828 | I10: =IF(OR(Data!$K$7="",Data!$AC$7=""),"n/a",(Data!$K$7-Data!$AC$7)/Data!$I$7) -> 0.13059035 | J10: =IFERROR(Data!$N$7/Data!$I$7,"n/a") -> 0.16905053 | K10: =IFERROR(Data!$L$7/Data!$I$7,"n/a") -> 0.086100426 | L10: =IFERROR(Data!$Q$7/Data!$I$7,"n/a") -> 0.060047778 | M10: =IFERROR(Data!$N$7/AVERAGE(Data!$S$7,Data!$AN$7),"n/a") -> 0.17243586 | N10: =IFERROR(Data!$Q$7/AVERAGE(Data!$U$7,Data!$AP$7),"n/a") -> 0.097160483 | O10: =IFERROR(Data!$Q$7/AVERAGE(Data!$S$7,Data!$AN$7),"n/a") -> 0.06125027 | P10: =IFERROR(Data!$I$7/AVERAGE(Data!$S$7,Data!$AN$7),"n/a") -> 1.0200256 | Q10: =IFERROR(Data!$T$7/Data!$S$7,"n/a") -> 0.36064227 | R10: =IFERROR(Data!$Z$7/Data!$U$7,"n/a") -> 0.19467559 | S10: =IFERROR(IF(Data!$N$7<=0,"n.m.",(Data!$Z$7-Data!$W$7)/Data!$N$7),"n/a") -> 0.24264414 | T10: =IFERROR(IF(Data!$O$7<=0,"n/a",Data!$L$7/Data!$O$7),"n/a") -> 14.039506 | U10: =IFERROR(Data!$X$7/Data!$Y$7,"n/a") -> 1.109287 | V10: =IFERROR(Data!$AA$7/Data!$I$7,"n/a") -> 0.14400924 | W10: =IFERROR(IF(Data!$N$7<=0,"n.m.",Data!$AA$7/Data!$N$7),"n/a") -> 0.85187097 | X10: =IFERROR(Data!$AB$7/Data!$I$7,"n/a") -> 0.10221406 | Y10: =IFERROR((Data!$AA$7-Data!$AB$7)/Data!$I$7,"n/a") -> 0.041795181 | Z10: =(Data!$AA$7-Data!$AB$7)/Data!$H$7/1000 -> 16.793519
A11: Hengli Petrochemical | B11: Private integrated refiner | C11: CNY | D11: =Data!$I$8/Data!$H$8/1000 -> 28.206944 | E11: =Data!$S$8/Data!$H$8/1000 -> 36.787627 | F11: =IFERROR(Data!$I$8/Data!$AD$8-1,"n/a") -> -0.14937897 | G11: =IFERROR(IF(Data!$AI$8<=0,"n.m.",Data!$N$8/Data!$AI$8-1),"n/a") -> 0.050992897 | H11: =IF(Data!$K$8="","n/a",Data!$K$8/Data!$I$8) -> 0.13187722 | I11: =IF(OR(Data!$K$8="",Data!$AC$8=""),"n/a",(Data!$K$8-Data!$AC$8)/Data!$I$8) -> 0.087275924 | J11: =IFERROR(Data!$N$8/Data!$I$8,"n/a") -> 0.12973111 | K11: =IFERROR(Data!$L$8/Data!$I$8,"n/a") -> 0.068084662 | L11: =IFERROR(Data!$Q$8/Data!$I$8,"n/a") -> 0.035179516 | M11: =IFERROR(Data!$N$8/AVERAGE(Data!$S$8,Data!$AN$8),"n/a") -> 0.097460258 | N11: =IFERROR(Data!$Q$8/AVERAGE(Data!$U$8,Data!$AP$8),"n/a") -> 0.10865859 | O11: =IFERROR(Data!$Q$8/AVERAGE(Data!$S$8,Data!$AN$8),"n/a") -> 0.026428548 | P11: =IFERROR(Data!$I$8/AVERAGE(Data!$S$8,Data!$AN$8),"n/a") -> 0.75124819 | Q11: =IFERROR(Data!$T$8/Data!$S$8,"n/a") -> 0.74532323 | R11: =IFERROR(Data!$Z$8/Data!$U$8,"n/a") -> 2.2703501 | S11: =IFERROR(IF(Data!$N$8<=0,"n.m.",(Data!$Z$8-Data!$W$8)/Data!$N$8),"n/a") -> 4.683778 | T11: =IFERROR(IF(Data!$O$8<=0,"n/a",Data!$L$8/Data!$O$8),"n/a") -> 3.3715043 | U11: =IFERROR(Data!$X$8/Data!$Y$8,"n/a") -> 0.55713189 | V11: =IFERROR(Data!$AA$8/Data!$I$8,"n/a") -> 0.15476755 | W11: =IFERROR(IF(Data!$N$8<=0,"n.m.",Data!$AA$8/Data!$N$8),"n/a") -> 1.1929872 | X11: =IFERROR(Data!$AB$8/Data!$I$8,"n/a") -> 0.035363954 | Y11: =IFERROR((Data!$AA$8-Data!$AB$8)/Data!$I$8,"n/a") -> 0.1194036 | Z11: =(Data!$AA$8-Data!$AB$8)/Data!$H$8/1000 -> 3.3680105
A12: Rongsheng Petrochemical | B12: Private integrated refiner | C12: CNY | D12: =Data!$I$9/Data!$H$9/1000 -> 43.291109 | E12: =Data!$S$9/Data!$H$9/1000 -> 54.233851 | F12: =IFERROR(Data!$I$9/Data!$AD$9-1,"n/a") -> -0.054683624 | G12: =IFERROR(IF(Data!$AI$9<=0,"n.m.",Data!$N$9/Data!$AI$9-1),"n/a") -> 0.079093821 | H12: =IF(Data!$K$9="","n/a",Data!$K$9/Data!$I$9) -> 0.12215167 | I12: =IF(OR(Data!$K$9="",Data!$AC$9=""),"n/a",(Data!$K$9-Data!$AC$9)/Data!$I$9) -> 0.043802905 | J12: =IFERROR(Data!$N$9/Data!$I$9,"n/a") -> 0.085277705 | K12: =IFERROR(Data!$L$9/Data!$I$9,"n/a") -> 0.029024622 | L12: =IFERROR(Data!$Q$9/Data!$I$9,"n/a") -> 0.010526974 | M12: =IFERROR(Data!$N$9/AVERAGE(Data!$S$9,Data!$AN$9),"n/a") -> 0.068853692 | N12: =IFERROR(Data!$Q$9/AVERAGE(Data!$U$9,Data!$AP$9),"n/a") -> 0.03387475 | O12: =IFERROR(Data!$Q$9/AVERAGE(Data!$S$9,Data!$AN$9),"n/a") -> 0.0084995368 | P12: =IFERROR(Data!$I$9/AVERAGE(Data!$S$9,Data!$AN$9),"n/a") -> 0.80740554 | Q12: =IFERROR(Data!$T$9/Data!$S$9,"n/a") -> 0.74913728 | R12: =IFERROR(Data!$Z$9/Data!$U$9,"n/a") -> 2.1457702 | S12: =IFERROR(IF(Data!$N$9<=0,"n.m.",(Data!$Z$9-Data!$W$9)/Data!$N$9),"n/a") -> 7.3948654 | T12: =IFERROR(IF(Data!$O$9<=0,"n/a",Data!$L$9/Data!$O$9),"n/a") -> 1.5366745 | U12: =IFERROR(Data!$X$9/Data!$Y$9,"n/a") -> 0.39336912 | V12: =IFERROR(Data!$AA$9/Data!$I$9,"n/a") -> 0.14712632 | W12: =IFERROR(IF(Data!$N$9<=0,"n.m.",Data!$AA$9/Data!$N$9),"n/a") -> 1.7252613 | X12: =IFERROR(Data!$AB$9/Data!$I$9,"n/a") -> 0.13829799 | Y12: =IFERROR((Data!$AA$9-Data!$AB$9)/Data!$I$9,"n/a") -> 0.0088283343 | Z12: =(Data!$AA$9-Data!$AB$9)/Data!$H$9/1000 -> 0.38218839
A13: Sinopec Shanghai Petrochemical | B13: Refining & petchem pure-play | C13: CNY | D13: =Data!$I$10/Data!$H$10/1000 -> 10.599409 | E13: =Data!$S$10/Data!$H$10/1000 -> 5.9695096 | F13: =IFERROR(Data!$I$10/Data!$AD$10-1,"n/a") -> -0.13278159 | G13: =IFERROR(IF(Data!$AI$10<=0,"n.m.",Data!$N$10/Data!$AI$10-1),"n/a") -> -0.46176695 | H13: =IF(Data!$K$10="","n/a",Data!$K$10/Data!$I$10) -> 0.15852153 | I13: =IF(OR(Data!$K$10="",Data!$AC$10=""),"n/a",(Data!$K$10-Data!$AC$10)/Data!$I$10) -> 0.0062619911 | J13: =IFERROR(Data!$N$10/Data!$I$10,"n/a") -> 0.02953638 | K13: =IFERROR(Data!$L$10/Data!$I$10,"n/a") -> -0.021051614 | L13: =IFERROR(Data!$Q$10/Data!$I$10,"n/a") -> -0.018929218 | M13: =IFERROR(Data!$N$10/AVERAGE(Data!$S$10,Data!$AN$10),"n/a") -> 0.052934177 | N13: =IFERROR(Data!$Q$10/AVERAGE(Data!$U$10,Data!$AP$10),"n/a") -> -0.05865607 | O13: =IFERROR(Data!$Q$10/AVERAGE(Data!$S$10,Data!$AN$10),"n/a") -> -0.033924352 | P13: =IFERROR(Data!$I$10/AVERAGE(Data!$S$10,Data!$AN$10),"n/a") -> 1.7921687 | Q13: =IFERROR(Data!$T$10/Data!$S$10,"n/a") -> 0.44482653 | R13: =IFERROR(Data!$Z$10/Data!$U$10,"n/a") -> 0.11091201 | S13: =IFERROR(IF(Data!$N$10<=0,"n.m.",(Data!$Z$10-Data!$W$10)/Data!$N$10),"n/a") -> -2.2110824 | T13: =IFERROR(IF(Data!$O$10<=0,"n/a",Data!$L$10/Data!$O$10),"n/a") -> -97.435195 | U13: =IFERROR(Data!$X$10/Data!$Y$10,"n/a") -> 0.93334528 | V13: =IFERROR(Data!$AA$10/Data!$I$10,"n/a") -> 0.026379645 | W13: =IFERROR(IF(Data!$N$10<=0,"n.m.",Data!$AA$10/Data!$N$10),"n/a") -> 0.89312382 | X13: =IFERROR(Data!$AB$10/Data!$I$10,"n/a") -> 0.041932562 | Y13: =IFERROR((Data!$AA$10-Data!$AB$10)/Data!$I$10,"n/a") -> -0.015552918 | Z13: =(Data!$AA$10-Data!$AB$10)/Data!$H$10/1000 -> -0.16485173
A15: Peer median - all peers | D15: =IFERROR(MEDIAN(D9:D13),"n/a") -> 43.291109 | E15: =IFERROR(MEDIAN(E9:E13),"n/a") -> 54.233851 | F15: =IFERROR(MEDIAN(F9:F13),"n/a") -> -0.094640798 | G15: =IFERROR(MEDIAN(G9:G13),"n/a") -> -0.029907707 | H15: =IFERROR(MEDIAN(H9:H13),"n/a") -> 0.15852153 | I15: =IFERROR(MEDIAN(I9:I13),"n/a") -> 0.068172927 | J15: =IFERROR(MEDIAN(J9:J13),"n/a") -> 0.085277705 | K15: =IFERROR(MEDIAN(K9:K13),"n/a") -> 0.029024622 | ... Z15: =IFERROR(MEDIAN(Z9:Z13),"n/a") -> 3.3680105
A16: Peer high - all peers | D16: =IFERROR(MAX(D9:D13),"n/a") -> 401.80516 | E16: =IFERROR(MAX(E9:E13),"n/a") -> 401.66335 | F16: =IFERROR(MAX(F9:F13),"n/a") -> -0.025021265 | G16: =IFERROR(MAX(G9:G13),"n/a") -> 0.079093821 | H16: =IFERROR(MAX(H9:H13),"n/a") -> 0.21586828 | I16: =IFERROR(MAX(I9:I13),"n/a") -> 0.13059035 | J16: =IFERROR(MAX(J9:J13),"n/a") -> 0.16905053 | K16: =IFERROR(MAX(K9:K13),"n/a") -> 0.086100426 | ... Z16: =IFERROR(MAX(Z9:Z13),"n/a") -> 16.793519
A17: Peer low - all peers | D17: =IFERROR(MIN(D9:D13),"n/a") -> 10.599409 | E17: =IFERROR(MIN(E9:E13),"n/a") -> 5.9695096 | F17: =IFERROR(MIN(F9:F13),"n/a") -> -0.14937897 | G17: =IFERROR(MIN(G9:G13),"n/a") -> -0.46176695 | H17: =IFERROR(MIN(H9:H13),"n/a") -> 0.12215167 | I17: =IFERROR(MIN(I9:I13),"n/a") -> 0.0062619911 | J17: =IFERROR(MIN(J9:J13),"n/a") -> 0.02953638 | K17: =IFERROR(MIN(K9:K13),"n/a") -> -0.021051614 | ... Z17: =IFERROR(MIN(Z9:Z13),"n/a") -> -0.16485173
A18: Peer median - State-owned majors | D18: =IFERROR(MEDIAN(D9:D10),"n/a") -> 396.13214 | E18: =IFERROR(MEDIAN(E9:E10),"n/a") -> 352.01817 | F18: =IFERROR(MEDIAN(F9:F10),"n/a") -> -0.059831031 | G18: =IFERROR(MEDIAN(G9:G10),"n/a") -> -0.072233096 | H18: =IFERROR(MEDIAN(H9:H10),"n/a") -> 0.18736414 | I18: =IFERROR(MEDIAN(I9:I10),"n/a") -> 0.099381637 | J18: =IFERROR(MEDIAN(J9:J10),"n/a") -> 0.11532855 | K18: =IFERROR(MEDIAN(K9:K10),"n/a") -> 0.05295184 | ... Z18: =IFERROR(MEDIAN(Z9:Z10),"n/a") -> 10.421658
A19: Peer median - Private integrated refiners | D19: =IFERROR(MEDIAN(D11:D12),"n/a") -> 35.749026 | E19: =IFERROR(MEDIAN(E11:E12),"n/a") -> 45.510739 | F19: =IFERROR(MEDIAN(F11:F12),"n/a") -> -0.1020313 | G19: =IFERROR(MEDIAN(G11:G12),"n/a") -> 0.065043359 | H19: =IFERROR(MEDIAN(H11:H12),"n/a") -> 0.12701444 | I19: =IFERROR(MEDIAN(I11:I12),"n/a") -> 0.065539414 | J19: =IFERROR(MEDIAN(J11:J12),"n/a") -> 0.10750441 | K19: =IFERROR(MEDIAN(K11:K12),"n/a") -> 0.048554642 | ... Z19: =IFERROR(MEDIAN(Z11:Z12),"n/a") -> 1.8750995
A21: Anchor (Sinochem Energy (中化能源)) minus all-peer median | D21: =IFERROR(D8-D15,"n/a") -> 11.991587 | E21: =IFERROR(E8-E15,"n/a") -> -39.443938 | F21: =IFERROR(F8-F15,"n/a") -> 0.017825701 | G21: =IFERROR(G8-G15,"n/a") -> 0.5949347 | H21: =IFERROR(H8-H15,"n/a") -> -0.1425419 | I21: =IFERROR(I8-I15,"n/a") -> -0.061332533 | J21: =IFERROR(J8-J15,"n/a") -> -0.07259514 | K21: =IFERROR(K8-K15,"n/a") -> -0.030080595 | ... Z21: =IFERROR(Z8-Z15,"n/a") -> -2.644954

Sheet Agriculture
A1: Agriculture - Syngenta Group entities vs crop-protection / seeds and crop-nutrition peers
A2: Syngenta Group itself discloses only sales and EBITDA publicly (USD 28.4bn / USD 4.4bn in FY2025); full statements exist for Syngenta AG (global CP + Seeds), ADAMA, Yangnong and Sinofert.
A3: FY2025, ratios computed from the 'Data' sheet. Amber rows = Sinochem Holdings group entities. Peer statistics exclude Sinochem entities. 'n.m.' = not meaningful (negative EBITDA); 'n/a' = not available.
D5: Scale | F5: Growth | H5: Profitability | L5: Returns | P5: Leverage & liquidity | U5: Cash generation
A6: Entity | B6: Group | C6: Ccy | D6: Revenue (USD bn) | E6: Total assets (USD bn) | F6: Revenue growth FY25 | G6: EBITDA growth FY25 | H6: Gross margin | I6: EBITDA margin | J6: EBIT margin | K6: Net margin | L6: EBITDA / avg assets | M6: ROE (NI / avg equity) | N6: ROA (NI / avg assets) | O6: Asset turnover (x) | P6: Liabilities / assets | Q6: Debt / equity | R6: Net debt / EBITDA (x) | S6: Interest cover (EBIT / interest, x) | T6: Current ratio (x) | U6: OCF / revenue | V6: OCF / EBITDA (cash conversion) | W6: Capex / revenue | X6: FCF margin | Y6: Free cash flow (USD bn)
A7: Direction (+1 higher is better, -1 lower is better, 0 informational) | D7: 0 | E7: 0 | F7: 1 | G7: 1 | H7: 1 | I7: 1 | J7: 1 | K7: 1 | L7: 1 | M7: 1 | N7: 1 | O7: 1 | P7: -1 | Q7: -1 | R7: -1 | S7: 1 | T7: 1 | U7: 1 | V7: 1 | W7: 0 | X7: 1 | Y7: 1
A8: Syngenta AG (global CP + Seeds) | B8: Sinochem - CP & seeds | C8: USD | D8: =Data!$I$11/Data!$H$11/1000 -> 16.999 | E8: =Data!$S$11/Data!$H$11/1000 -> 30.799 | F8: =IFERROR(Data!$I$11/Data!$AD$11-1,"n/a") -> 0.0010600082 | G8: =IFERROR(IF(Data!$AI$11<=0,"n.m.",Data!$N$11/Data!$AI$11-1),"n/a") -> -0.080715532 | H8: =IF(Data!$K$11="","n/a",Data!$K$11/Data!$I$11) -> 0.39519972 | I8: =IFERROR(Data!$N$11/Data!$I$11,"n/a") -> 0.12394847 | J8: =IFERROR(Data!$L$11/Data!$I$11,"n/a") -> 0.07229837 | K8: =IFERROR(Data!$Q$11/Data!$I$11,"n/a") -> -0.0089417025 | L8: =IFERROR(Data!$N$11/AVERAGE(Data!$S$11,Data!$AN$11),"n/a") -> 0.069948875 | M8: =IFERROR(Data!$Q$11/AVERAGE(Data!$U$11,Data!$AP$11),"n/a") -> -0.020753687 | N8: =IFERROR(Data!$Q$11/AVERAGE(Data!$S$11,Data!$AN$11),"n/a") -> -0.0050461457 | O8: =IFERROR(Data!$I$11/AVERAGE(Data!$S$11,Data!$AN$11),"n/a") -> 0.56433836 | P8: =IFERROR(Data!$T$11/Data!$S$11,"n/a") -> 0.76015455 | Q8: =IFERROR(Data!$Z$11/Data!$U$11,"n/a") -> 1.4256126 | R8: =IFERROR(IF(Data!$N$11<=0,"n.m.",(Data!$Z$11-Data!$W$11)/Data!$N$11),"n/a") -> 4.6767916 | S8: =IFERROR(IF(Data!$O$11<=0,"n/a",Data!$L$11/Data!$O$11),"n/a") -> 1.5878553 | T8: =IFERROR(Data!$X$11/Data!$Y$11,"n/a") -> 1.0596506 | U8: =IFERROR(Data!$AA$11/Data!$I$11,"n/a") -> 0.089769986 | V8: =IFERROR(IF(Data!$N$11<=0,"n.m.",Data!$AA$11/Data!$N$11),"n/a") -> 0.72425249 | W8: =IFERROR(Data!$AB$11/Data!$I$11,"n/a") -> 0.071592447 | X8: =IFERROR((Data!$AA$11-Data!$AB$11)/Data!$I$11,"n/a") -> 0.01817754 | Y8: =(Data!$AA$11-Data!$AB$11)/Data!$H$11/1000 -> 0.309
A9: ADAMA | B9: Sinochem - CP (generics) | C9: CNY | D9: =Data!$I$12/Data!$H$12/1000 -> 4.0601187 | E9: =Data!$S$12/Data!$H$12/1000 -> 6.7981431 | F9: =IFERROR(Data!$I$12/Data!$AD$12-1,"n/a") -> -0.018429841 | G9: =IFERROR(IF(Data!$AI$12<=0,"n.m.",Data!$N$12/Data!$AI$12-1),"n/a") -> 0.96135309 | H9: =IF(Data!$K$12="","n/a",Data!$K$12/Data!$I$12) -> 0.26335609 | I9: =IFERROR(Data!$N$12/Data!$I$12,"n/a") -> 0.11881538 | J9: =IFERROR(Data!$L$12/Data!$I$12,"n/a") -> 0.046133982 | K9: =IFERROR(Data!$Q$12/Data!$I$12,"n/a") -> -0.036128311 | L9: =IFERROR(Data!$N$12/AVERAGE(Data!$S$12,Data!$AN$12),"n/a") -> 0.069811845 | M9: =IFERROR(Data!$Q$12/AVERAGE(Data!$U$12,Data!$AP$12),"n/a") -> -0.057195435 | N9: =IFERROR(Data!$Q$12/AVERAGE(Data!$S$12,Data!$AN$12),"n/a") -> -0.021227757 | O9: =IFERROR(Data!$I$12/AVERAGE(Data!$S$12,Data!$AN$12),"n/a") -> 0.58756572 | P9: =IFERROR(Data!$T$12/Data!$S$12,"n/a") -> 0.63735062 | Q9: =IFERROR(Data!$Z$12/Data!$U$12,"n/a") -> 1.0043461 | R9: =IFERROR(IF(Data!$N$12<=0,"n.m.",(Data!$Z$12-Data!$W$12)/Data!$N$12),"n/a") -> 4.1294722 | S9: =IFERROR(IF(Data!$O$12<=0,"n/a",Data!$L$12/Data!$O$12),"n/a") -> 1.3074426 | T9: =IFERROR(Data!$X$12/Data!$Y$12,"n/a") -> 1.1418523 | U9: =IFERROR(Data!$AA$12/Data!$I$12,"n/a") -> 0.13987739 | V9: =IFERROR(IF(Data!$N$12<=0,"n.m.",Data!$AA$12/Data!$N$12),"n/a") -> 1.1772667 | W9: =IFERROR(Data!$AB$12/Data!$I$12,"n/a") -> 0.041930467 | X9: =IFERROR((Data!$AA$12-Data!$AB$12)/Data!$I$12,"n/a") -> 0.097946918 | Y9: =(Data!$AA$12-Data!$AB$12)/Data!$H$12/1000 -> 0.39767611
A10: Yangnong Chemical | B10: Sinochem - CP (AI) | C10: CNY | D10: =Data!$I$13/Data!$H$13/1000 -> 1.6650902 | E10: =Data!$S$13/Data!$H$13/1000 -> 2.5510613 | F10: =IFERROR(Data!$I$13/Data!$AD$13-1,"n/a") -> 0.13758373 | G10: =IFERROR(IF(Data!$AI$13<=0,"n.m.",Data!$N$13/Data!$AI$13-1),"n/a") -> 0.48075406 | H10: =IF(Data!$K$13="","n/a",Data!$K$13/Data!$I$13) -> 0.21992105 | I10: =IFERROR(Data!$N$13/Data!$I$13,"n/a") -> 0.25800367 | J10: =IFERROR(Data!$L$13/Data!$I$13,"n/a") -> 0.12301427 | K10: =IFERROR(Data!$Q$13/Data!$I$13,"n/a") -> 0.10838565 | L10: =IFERROR(Data!$N$13/AVERAGE(Data!$S$13,Data!$AN$13),"n/a") -> 0.17085077 | M10: =IFERROR(Data!$Q$13/AVERAGE(Data!$U$13,Data!$AP$13),"n/a") -> 0.1168737 | N10: =IFERROR(Data!$Q$13/AVERAGE(Data!$S$13,Data!$AN$13),"n/a") -> 0.071773285 | O10: =IFERROR(Data!$I$13/AVERAGE(Data!$S$13,Data!$AN$13),"n/a") -> 0.66220286 | P10: =IFERROR(Data!$T$13/Data!$S$13,"n/a") -> 0.36908817 | Q10: =IFERROR(Data!$Z$13/Data!$U$13,"n/a") -> 0.079383128 | R10: =IFERROR(IF(Data!$N$13<=0,"n.m.",(Data!$Z$13-Data!$W$13)/Data!$N$13),"n/a") -> -0.13738427 | S10: =IFERROR(IF(Data!$O$13<=0,"n/a",Data!$L$13/Data!$O$13),"n/a") -> 35.282383 | T10: =IFERROR(Data!$X$13/Data!$Y$13,"n/a") -> 1.3782997 | U10: =IFERROR(Data!$AA$13/Data!$I$13,"n/a") -> 0.18674381 | V10: =IFERROR(IF(Data!$N$13<=0,"n.m.",Data!$AA$13/Data!$N$13),"n/a") -> 0.72380293 | W10: =IFERROR(Data!$AB$13/Data!$I$13,"n/a") -> 0.080985117 | X10: =IFERROR((Data!$AA$13-Data!$AB$13)/Data!$I$13,"n/a") -> 0.1057587 | Y10: =(Data!$AA$13-Data!$AB$13)/Data!$H$13/1000 -> 0.17609777
A11: Sinofert | B11: Sinochem - fertilizer | C11: CNY | D11: =Data!$I$14/Data!$H$14/1000 -> 3.2631652 | E11: =Data!$S$14/Data!$H$14/1000 -> 3.308788 | F11: =IFERROR(Data!$I$14/Data!$AD$14-1,"n/a") -> 0.093969655 | G11: =IFERROR(IF(Data!$AI$14<=0,"n.m.",Data!$N$14/Data!$AI$14-1),"n/a") -> 0.30584267 | H11: =IF(Data!$K$14="","n/a",Data!$K$14/Data!$I$14) -> 0.12437368 | I11: =IFERROR(Data!$N$14/Data!$I$14,"n/a") -> 0.085335083 | J11: =IFERROR(Data!$L$14/Data!$I$14,"n/a") -> 0.064394886 | K11: =IFERROR(Data!$Q$14/Data!$I$14,"n/a") -> 0.054734912 | L11: =IFERROR(Data!$N$14/AVERAGE(Data!$S$14,Data!$AN$14),"n/a") -> 0.088218377 | M11: =IFERROR(Data!$Q$14/AVERAGE(Data!$U$14,Data!$AP$14),"n/a") -> 0.11528546 | N11: =IFERROR(Data!$Q$14/AVERAGE(Data!$S$14,Data!$AN$14),"n/a") -> 0.05658429 | O11: =IFERROR(Data!$I$14/AVERAGE(Data!$S$14,Data!$AN$14),"n/a") -> 1.0337879 | P11: =IFERROR(Data!$T$14/Data!$S$14,"n/a") -> 0.51440152 | Q11: =IFERROR(Data!$Z$14/Data!$U$14,"n/a") -> 0.13158875 | R11: =IFERROR(IF(Data!$N$14<=0,"n.m.",(Data!$Z$14-Data!$W$14)/Data!$N$14),"n/a") -> -0.71581974 | S11: =IFERROR(IF(Data!$O$14<=0,"n/a",Data!$L$14/Data!$O$14),"n/a") -> 33.228157 | T11: =IFERROR(Data!$X$14/Data!$Y$14,"n/a") -> 1.2378762 | U11: =IFERROR(Data!$AA$14/Data!$I$14,"n/a") -> 0.085705885 | V11: =IFERROR(IF(Data!$N$14<=0,"n.m.",Data!$AA$14/Data!$N$14),"n/a") -> 1.0043452 | W11: =IFERROR(Data!$AB$14/Data!$I$14,"n/a") -> 0.01475147 | X11: =IFERROR((Data!$AA$14-Data!$AB$14)/Data!$I$14,"n/a") -> 0.070954415 | Y11: =(Data!$AA$14-Data!$AB$14)/Data!$H$14/1000 -> 0.23153598
A12: Corteva | B12: CP & seeds peer | C12: USD | D12: =Data!$I$15/Data!$H$15/1000 -> 17.401 | E12: =Data!$S$15/Data!$H$15/1000 -> 42.845 | F12: =IFERROR(Data!$I$15/Data!$AD$15-1,"n/a") -> 0.029157795 | G12: =IFERROR(IF(Data!$AI$15<=0,"n.m.",Data!$N$15/Data!$AI$15-1),"n/a") -> 0.12285192 | H12: =IF(Data!$K$15="","n/a",Data!$K$15/Data!$I$15) -> 0.47290386 | I12: =IFERROR(Data!$N$15/Data!$I$15,"n/a") -> 0.17648411 | J12: =IFERROR(Data!$L$15/Data!$I$15,"n/a") -> 0.10735015 | K12: =IFERROR(Data!$Q$15/Data!$I$15,"n/a") -> 0.063502098 | L12: =IFERROR(Data!$N$15/AVERAGE(Data!$S$15,Data!$AN$15),"n/a") -> 0.073407434 | M12: =IFERROR(Data!$Q$15/AVERAGE(Data!$U$15,Data!$AP$15),"n/a") -> 0.045646067 | N12: =IFERROR(Data!$Q$15/AVERAGE(Data!$S$15,Data!$AN$15),"n/a") -> 0.02641329 | O12: =IFERROR(Data!$I$15/AVERAGE(Data!$S$15,Data!$AN$15),"n/a") -> 0.41594359 | P12: =IFERROR(Data!$T$15/Data!$S$15,"n/a") -> 0.43083207 | Q12: =IFERROR(Data!$Z$15/Data!$U$15,"n/a") -> 0.10579841 | R12: =IFERROR(IF(Data!$N$15<=0,"n.m.",(Data!$Z$15-Data!$W$15)/Data!$N$15),"n/a") -> -0.63204168 | S12: =IFERROR(IF(Data!$O$15<=0,"n/a",Data!$L$15/Data!$O$15),"n/a") -> 10.377778 | T12: =IFERROR(Data!$X$15/Data!$Y$15,"n/a") -> 1.4296907 | U12: =IFERROR(Data!$AA$15/Data!$I$15,"n/a") -> 0.19573588 | V12: =IFERROR(IF(Data!$N$15<=0,"n.m.",Data!$AA$15/Data!$N$15),"n/a") -> 1.109085 | W12: =IFERROR(Data!$AB$15/Data!$I$15,"n/a") -> 0.033963565 | X12: =IFERROR((Data!$AA$15-Data!$AB$15)/Data!$I$15,"n/a") -> 0.16177231 | Y12: =(Data!$AA$15-Data!$AB$15)/Data!$H$15/1000 -> 2.815
A13: FMC Corp | B13: CP & seeds peer | C13: USD | D13: =Data!$I$16/Data!$H$16/1000 -> 3.4674 | E13: =Data!$S$16/Data!$H$16/1000 -> 9.6872 | F13: =IFERROR(Data!$I$16/Data!$AD$16-1,"n/a") -> -0.18339182 | G13: =IFERROR(IF(Data!$AI$16<=0,"n.m.",Data!$N$16/Data!$AI$16-1),"n/a") -> -3.1304921 | H13: =IF(Data!$K$16="","n/a",Data!$K$16/Data!$I$16) -> 0.37001788 | I13: =IFERROR(Data!$N$16/Data!$I$16,"n/a") -> -0.41953625 | J13: =IFERROR(Data!$L$16/Data!$I$16,"n/a") -> -0.46960258 | K13: =IFERROR(Data!$Q$16/Data!$I$16,"n/a") -> -0.64526735 | L13: =IFERROR(Data!$N$16/AVERAGE(Data!$S$16,Data!$AN$16),"n/a") -> -0.13633233 | M13: =IFERROR(Data!$Q$16/AVERAGE(Data!$U$16,Data!$AP$16),"n/a") -> -0.67720992 | N13: =IFERROR(Data!$Q$16/AVERAGE(Data!$S$16,Data!$AN$16),"n/a") -> -0.20968581 | O13: =IFERROR(Data!$I$16/AVERAGE(Data!$S$16,Data!$AN$16),"n/a") -> 0.32495958 | P13: =IFERROR(Data!$T$16/Data!$S$16,"n/a") -> 0.78333265 | Q13: =IFERROR(Data!$Z$16/Data!$U$16,"n/a") -> 1.9414455 | R13: =IFERROR(IF(Data!$N$16<=0,"n.m.",(Data!$Z$16-Data!$W$16)/Data!$N$16),"n/a") -> n.m. | S13: =IFERROR(IF(Data!$O$16<=0,"n/a",Data!$L$16/Data!$O$16),"n/a") -> -6.7959098 | T13: =IFERROR(Data!$X$16/Data!$Y$16,"n/a") -> 1.3205336 | U13: =IFERROR(Data!$AA$16/Data!$I$16,"n/a") -> -0.0017880833 | V13: =IFERROR(IF(Data!$N$16<=0,"n.m.",Data!$AA$16/Data!$N$16),"n/a") -> n.m. | W13: =IFERROR(Data!$AB$16/Data!$I$16,"n/a") -> 0.027772971 | X13: =IFERROR((Data!$AA$16-Data!$AB$16)/Data!$I$16,"n/a") -> -0.029561054 | Y13: =(Data!$AA$16-Data!$AB$16)/Data!$H$16/1000 -> -0.1025
A14: Jiangshan Agrochemical | B14: CP & seeds peer | C14: CNY | D14: =Data!$I$17/Data!$H$17/1000 -> 0.81584921 | E14: =Data!$S$17/Data!$H$17/1000 -> 1.3648573 | F14: =IFERROR(Data!$I$17/Data!$AD$17-1,"n/a") -> 0.070807614 | G14: =IFERROR(IF(Data!$AI$17<=0,"n.m.",Data!$N$17/Data!$AI$17-1),"n/a") -> 0.24554065 | H14: =IF(Data!$K$17="","n/a",Data!$K$17/Data!$I$17) -> 0.17363965 | I14: =IFERROR(Data!$N$17/Data!$I$17,"n/a") -> 0.15854729 | J14: =IFERROR(Data!$L$17/Data!$I$17,"n/a") -> 0.11663496 | K14: =IFERROR(Data!$Q$17/Data!$I$17,"n/a") -> 0.090522333 | L14: =IFERROR(Data!$N$17/AVERAGE(Data!$S$17,Data!$AN$17),"n/a") -> 0.10043099 | M14: =IFERROR(Data!$Q$17/AVERAGE(Data!$U$17,Data!$AP$17),"n/a") -> 0.12758959 | N14: =IFERROR(Data!$Q$17/AVERAGE(Data!$S$17,Data!$AN$17),"n/a") -> 0.057340922 | O14: =IFERROR(Data!$I$17/AVERAGE(Data!$S$17,Data!$AN$17),"n/a") -> 0.63344503 | P14: =IFERROR(Data!$T$17/Data!$S$17,"n/a") -> 0.55620711 | Q14: =IFERROR(Data!$Z$17/Data!$U$17,"n/a") -> 0.55742967 | R14: =IFERROR(IF(Data!$N$17<=0,"n.m.",(Data!$Z$17-Data!$W$17)/Data!$N$17),"n/a") -> 1.6612416 | S14: =IFERROR(IF(Data!$O$17<=0,"n/a",Data!$L$17/Data!$O$17),"n/a") -> 27.694264 | T14: =IFERROR(Data!$X$17/Data!$Y$17,"n/a") -> 1.018195 | U14: =IFERROR(Data!$AA$17/Data!$I$17,"n/a") -> 0.050791678 | V14: =IFERROR(IF(Data!$N$17<=0,"n.m.",Data!$AA$17/Data!$N$17),"n/a") -> 0.32035665 | W14: =IFERROR(Data!$AB$17/Data!$I$17,"n/a") -> 0.21912304 | X14: =IFERROR((Data!$AA$17-Data!$AB$17)/Data!$I$17,"n/a") -> -0.16833136 | Y14: =(Data!$AA$17-Data!$AB$17)/Data!$H$17/1000 -> -0.13733301
A15: Lier Chemical | B15: CP & seeds peer | C15: CNY | D15: =Data!$I$18/Data!$H$18/1000 -> 1.2635368 | E15: =Data!$S$18/Data!$H$18/1000 -> 2.2616906 | F15: =IFERROR(Data!$I$18/Data!$AD$18-1,"n/a") -> 0.23210223 | G15: =IFERROR(IF(Data!$AI$18<=0,"n.m.",Data!$N$18/Data!$AI$18-1),"n/a") -> 0.4929644 | H15: =IF(Data!$K$18="","n/a",Data!$K$18/Data!$I$18) -> 0.1891497 | I15: =IFERROR(Data!$N$18/Data!$I$18,"n/a") -> 0.19961569 | J15: =IFERROR(Data!$L$18/Data!$I$18,"n/a") -> 0.089486347 | K15: =IFERROR(Data!$Q$18/Data!$I$18,"n/a") -> 0.064468346 | L15: =IFERROR(Data!$N$18/AVERAGE(Data!$S$18,Data!$AN$18),"n/a") -> 0.11318677 | M15: =IFERROR(Data!$Q$18/AVERAGE(Data!$U$18,Data!$AP$18),"n/a") -> 0.063587882 | N15: =IFERROR(Data!$Q$18/AVERAGE(Data!$S$18,Data!$AN$18),"n/a") -> 0.036555062 | O15: =IFERROR(Data!$I$18/AVERAGE(Data!$S$18,Data!$AN$18),"n/a") -> 0.56702343 | P15: =IFERROR(Data!$T$18/Data!$S$18,"n/a") -> 0.42603726 | Q15: =IFERROR(Data!$Z$18/Data!$U$18,"n/a") -> 0.36719622 | R15: =IFERROR(IF(Data!$N$18<=0,"n.m.",(Data!$Z$18-Data!$W$18)/Data!$N$18),"n/a") -> 1.3321827 | S15: =IFERROR(IF(Data!$O$18<=0,"n/a",Data!$L$18/Data!$O$18),"n/a") -> 9.6192153 | T15: =IFERROR(Data!$X$18/Data!$Y$18,"n/a") -> 1.3109117 | U15: =IFERROR(Data!$AA$18/Data!$I$18,"n/a") -> 0.14394987 | V15: =IFERROR(IF(Data!$N$18<=0,"n.m.",Data!$AA$18/Data!$N$18),"n/a") -> 0.72113505 | W15: =IFERROR(Data!$AB$18/Data!$I$18,"n/a") -> 0.12025251 | X15: =IFERROR((Data!$AA$18-Data!$AB$18)/Data!$I$18,"n/a") -> 0.023697361 | Y15: =(Data!$AA$18-Data!$AB$18)/Data!$H$18/1000 -> 0.029942488
A16: Nutrien | B16: Crop-nutrition peer | C16: USD | D16: =Data!$I$19/Data!$H$19/1000 -> 26.885 | E16: =Data!$S$19/Data!$H$19/1000 -> 52.301 | F16: =IFERROR(Data!$I$19/Data!$AD$19-1,"n/a") -> 0.035153242 | G16: =IFERROR(IF(Data!$AI$19<=0,"n.m.",Data!$N$19/Data!$AI$19-1),"n/a") -> 0.45530393 | H16: =IF(Data!$K$19="","n/a",Data!$K$19/Data!$I$19) -> 0.31047052 | I16: =IFERROR(Data!$N$19/Data!$I$19,"n/a") -> 0.2270783 | J16: =IFERROR(Data!$L$19/Data!$I$19,"n/a") -> 0.13896225 | K16: =IFERROR(Data!$Q$19/Data!$I$19,"n/a") -> 0.085437977 | L16: =IFERROR(Data!$N$19/AVERAGE(Data!$S$19,Data!$AN$19),"n/a") -> 0.11724489 | M16: =IFERROR(Data!$Q$19/AVERAGE(Data!$U$19,Data!$AP$19),"n/a") -> 0.092236031 | N16: =IFERROR(Data!$Q$19/AVERAGE(Data!$S$19,Data!$AN$19),"n/a") -> 0.04411327 | O16: =IFERROR(Data!$I$19/AVERAGE(Data!$S$19,Data!$AN$19),"n/a") -> 0.51631922 | P16: =IFERROR(Data!$T$19/Data!$S$19,"n/a") -> 0.51501883 | Q16: =IFERROR(Data!$Z$19/Data!$U$19,"n/a") -> 0.47384191 | R16: =IFERROR(IF(Data!$N$19<=0,"n.m.",(Data!$Z$19-Data!$W$19)/Data!$N$19),"n/a") -> 1.8538903 | S16: =IFERROR(IF(Data!$O$19<=0,"n/a",Data!$L$19/Data!$O$19),"n/a") -> 5.4381368 | T16: =IFERROR(Data!$X$19/Data!$Y$19,"n/a") -> 1.3358391 | U16: =IFERROR(Data!$AA$19/Data!$I$19,"n/a") -> 0.14904222 | V16: =IFERROR(IF(Data!$N$19<=0,"n.m.",Data!$AA$19/Data!$N$19),"n/a") -> 0.65634726 | W16: =IFERROR(Data!$AB$19/Data!$I$19,"n/a") -> 0.074576902 | X16: =IFERROR((Data!$AA$19-Data!$AB$19)/Data!$I$19,"n/a") -> 0.074465315 | Y16: =(Data!$AA$19-Data!$AB$19)/Data!$H$19/1000 -> 2.002
A17: Mosaic | B17: Crop-nutrition peer | C17: USD | D17: =Data!$I$20/Data!$H$20/1000 -> 12.0524 | E17: =Data!$S$20/Data!$H$20/1000 -> 24.4801 | F17: =IFERROR(Data!$I$20/Data!$AD$20-1,"n/a") -> 0.083576078 | G17: =IFERROR(IF(Data!$AI$20<=0,"n.m.",Data!$N$20/Data!$AI$20-1),"n/a") -> 0.13624772 | H17: =IF(Data!$K$20="","n/a",Data!$K$20/Data!$I$20) -> 0.1578026 | I17: =IFERROR(Data!$N$20/Data!$I$20,"n/a") -> 0.15527198 | J17: =IFERROR(Data!$L$20/Data!$I$20,"n/a") -> 0.068160698 | K17: =IFERROR(Data!$Q$20/Data!$I$20,"n/a") -> 0.047741529 | L17: =IFERROR(Data!$N$20/AVERAGE(Data!$S$20,Data!$AN$20),"n/a") -> 0.078955196 | M17: =IFERROR(Data!$Q$20/AVERAGE(Data!$U$20,Data!$AP$20),"n/a") -> 0.048253798 | N17: =IFERROR(Data!$Q$20/AVERAGE(Data!$S$20,Data!$AN$20),"n/a") -> 0.024276381 | O17: =IFERROR(Data!$I$20/AVERAGE(Data!$S$20,Data!$AN$20),"n/a") -> 0.5084961 | P17: =IFERROR(Data!$T$20/Data!$S$20,"n/a") -> 0.50023897 | Q17: =IFERROR(Data!$Z$20/Data!$U$20,"n/a") -> 0.41309607 | R17: =IFERROR(IF(Data!$N$20<=0,"n.m.",(Data!$Z$20-Data!$W$20)/Data!$N$20),"n/a") -> 2.5527947 | S17: =IFERROR(IF(Data!$O$20<=0,"n/a",Data!$L$20/Data!$O$20),"n/a") -> 3.4016563 | T17: =IFERROR(Data!$X$20/Data!$Y$20,"n/a") -> 1.3150296 | U17: =IFERROR(Data!$AA$20/Data!$I$20,"n/a") -> 0.068434503 | V17: =IFERROR(IF(Data!$N$20<=0,"n.m.",Data!$AA$20/Data!$N$20),"n/a") -> 0.44073955 | W17: =IFERROR(Data!$AB$20/Data!$I$20,"n/a") -> 0.11279081 | X17: =IFERROR((Data!$AA$20-Data!$AB$20)/Data!$I$20,"n/a") -> -0.044356311 | Y17: =(Data!$AA$20-Data!$AB$20)/Data!$H$20/1000 -> -0.5346
A18: Yuntianhua | B18: Crop-nutrition peer | C18: CNY | D18: =Data!$I$21/Data!$H$21/1000 -> 6.7912644 | E18: =Data!$S$21/Data!$H$21/1000 -> 7.0616451 | F18: =IFERROR(Data!$I$21/Data!$AD$21-1,"n/a") -> -0.21473614 | G18: =IFERROR(IF(Data!$AI$21<=0,"n.m.",Data!$N$21/Data!$AI$21-1),"n/a") -> -0.051394255 | H18: =IF(Data!$K$21="","n/a",Data!$K$21/Data!$I$21) -> 0.20213773 | I18: =IFERROR(Data!$N$21/Data!$I$21,"n/a") -> 0.20907611 | J18: =IFERROR(Data!$L$21/Data!$I$21,"n/a") -> 0.14213834 | K18: =IFERROR(Data!$Q$21/Data!$I$21,"n/a") -> 0.11355406 | L18: =IFERROR(Data!$N$21/AVERAGE(Data!$S$21,Data!$AN$21),"n/a") -> 0.1987309 | M18: =IFERROR(Data!$Q$21/AVERAGE(Data!$U$21,Data!$AP$21),"n/a") -> 0.21472254 | N18: =IFERROR(Data!$Q$21/AVERAGE(Data!$S$21,Data!$AN$21),"n/a") -> 0.10793533 | O18: =IFERROR(Data!$I$21/AVERAGE(Data!$S$21,Data!$AN$21),"n/a") -> 0.95051941 | P18: =IFERROR(Data!$T$21/Data!$S$21,"n/a") -> 0.47171889 | Q18: =IFERROR(Data!$Z$21/Data!$U$21,"n/a") -> 0.43098386 | R18: =IFERROR(IF(Data!$N$21<=0,"n.m.",(Data!$Z$21-Data!$W$21)/Data!$N$21),"n/a") -> 0.64022272 | S18: =IFERROR(IF(Data!$O$21<=0,"n/a",Data!$L$21/Data!$O$21),"n/a") -> 18.561641 | T18: =IFERROR(Data!$X$21/Data!$Y$21,"n/a") -> 0.84972303 | U18: =IFERROR(Data!$AA$21/Data!$I$21,"n/a") -> 0.18769454 | V18: =IFERROR(IF(Data!$N$21<=0,"n.m.",Data!$AA$21/Data!$N$21),"n/a") -> 0.89773309 | W18: =IFERROR(Data!$AB$21/Data!$I$21,"n/a") -> 0.047171694 | X18: =IFERROR((Data!$AA$21-Data!$AB$21)/Data!$I$21,"n/a") -> 0.14052285 | Y18: =(Data!$AA$21-Data!$AB$21)/Data!$H$21/1000 -> 0.95432782
A19: Salt Lake Potash (青海盐湖) | B19: Crop-nutrition peer | C19: CNY | D19: =Data!$I$22/Data!$H$22/1000 -> 2.1743925 | E19: =Data!$S$22/Data!$H$22/1000 -> 8.5795921 | F19: =IFERROR(Data!$I$22/Data!$AD$22-1,"n/a") -> 0.024258034 | G19: =IFERROR(IF(Data!$AI$22<=0,"n.m.",Data!$N$22/Data!$AI$22-1),"n/a") -> 0.21404045 | H19: =IF(Data!$K$22="","n/a",Data!$K$22/Data!$I$22) -> 0.57855137 | I19: =IFERROR(Data!$N$22/Data!$I$22,"n/a") -> 0.51628237 | J19: =IFERROR(Data!$L$22/Data!$I$22,"n/a") -> 0.45031199 | K19: =IFERROR(Data!$Q$22/Data!$I$22,"n/a") -> 0.57715181 | L19: =IFERROR(Data!$N$22/AVERAGE(Data!$S$22,Data!$AN$22),"n/a") -> 0.1496636 | M19: =IFERROR(Data!$Q$22/AVERAGE(Data!$U$22,Data!$AP$22),"n/a") -> 0.19867853 | N19: =IFERROR(Data!$Q$22/AVERAGE(Data!$S$22,Data!$AN$22),"n/a") -> 0.16730887 | O19: =IFERROR(Data!$I$22/AVERAGE(Data!$S$22,Data!$AN$22),"n/a") -> 0.28988711 | P19: =IFERROR(Data!$T$22/Data!$S$22,"n/a") -> 0.17489351 | Q19: =IFERROR(Data!$Z$22/Data!$U$22,"n/a") -> 0.025381152 | R19: =IFERROR(IF(Data!$N$22<=0,"n.m.",(Data!$Z$22-Data!$W$22)/Data!$N$22),"n/a") -> -2.8905036 | S19: =IFERROR(IF(Data!$O$22<=0,"n/a",Data!$L$22/Data!$O$22),"n/a") -> 347.57735 | T19: =IFERROR(Data!$X$22/Data!$Y$22,"n/a") -> 4.8589045 | U19: =IFERROR(Data!$AA$22/Data!$I$22,"n/a") -> 0.65548681 | V19: =IFERROR(IF(Data!$N$22<=0,"n.m.",Data!$AA$22/Data!$N$22),"n/a") -> 1.2696285 | W19: =IFERROR(Data!$AB$22/Data!$I$22,"n/a") -> 0.10589369 | X19: =IFERROR((Data!$AA$22-Data!$AB$22)/Data!$I$22,"n/a") -> 0.54959312 | Y19: =(Data!$AA$22-Data!$AB$22)/Data!$H$22/1000 -> 1.1950311
A21: Peer median - all peers | D21: =IFERROR(MEDIAN(D12:D19),"n/a") -> 5.1293322 | E21: =IFERROR(MEDIAN(E12:E19),"n/a") -> 9.133396 | F21: =IFERROR(MEDIAN(F12:F19),"n/a") -> 0.032155519 | G21: =IFERROR(MEDIAN(G12:G19),"n/a") -> 0.17514409 | H21: =IFERROR(MEDIAN(H12:H19),"n/a") -> 0.25630413 | I21: =IFERROR(MEDIAN(I12:I19),"n/a") -> 0.1880499 | J21: =IFERROR(MEDIAN(J12:J19),"n/a") -> 0.11199256 | K21: =IFERROR(MEDIAN(K12:K19),"n/a") -> 0.074953161 | ... Y21: =IFERROR(MEDIAN(Y12:Y19),"n/a") -> 0.49213515
A22: Peer high - all peers | D22: =IFERROR(MAX(D12:D19),"n/a") -> 26.885 | E22: =IFERROR(MAX(E12:E19),"n/a") -> 52.301 | F22: =IFERROR(MAX(F12:F19),"n/a") -> 0.23210223 | G22: =IFERROR(MAX(G12:G19),"n/a") -> 0.4929644 | H22: =IFERROR(MAX(H12:H19),"n/a") -> 0.57855137 | I22: =IFERROR(MAX(I12:I19),"n/a") -> 0.51628237 | J22: =IFERROR(MAX(J12:J19),"n/a") -> 0.45031199 | K22: =IFERROR(MAX(K12:K19),"n/a") -> 0.57715181 | ... Y22: =IFERROR(MAX(Y12:Y19),"n/a") -> 2.815
A23: Peer low - all peers | D23: =IFERROR(MIN(D12:D19),"n/a") -> 0.81584921 | E23: =IFERROR(MIN(E12:E19),"n/a") -> 1.3648573 | F23: =IFERROR(MIN(F12:F19),"n/a") -> -0.21473614 | G23: =IFERROR(MIN(G12:G19),"n/a") -> -3.1304921 | H23: =IFERROR(MIN(H12:H19),"n/a") -> 0.1578026 | I23: =IFERROR(MIN(I12:I19),"n/a") -> -0.41953625 | J23: =IFERROR(MIN(J12:J19),"n/a") -> -0.46960258 | K23: =IFERROR(MIN(K12:K19),"n/a") -> -0.64526735 | ... Y23: =IFERROR(MIN(Y12:Y19),"n/a") -> -0.5346
A24: Peer median - Crop-protection & seeds peers | D24: =IFERROR(MEDIAN(D12:D15),"n/a") -> 2.3654684 | E24: =IFERROR(MEDIAN(E12:E15),"n/a") -> 5.9744453 | F24: =IFERROR(MEDIAN(F12:F15),"n/a") -> 0.049982705 | G24: =IFERROR(MEDIAN(G12:G15),"n/a") -> 0.18419628 | H24: =IFERROR(MEDIAN(H12:H15),"n/a") -> 0.27958379 | I24: =IFERROR(MEDIAN(I12:I15),"n/a") -> 0.1675157 | J24: =IFERROR(MEDIAN(J12:J15),"n/a") -> 0.09841825 | K24: =IFERROR(MEDIAN(K12:K15),"n/a") -> 0.063985222 | ... Y24: =IFERROR(MEDIAN(Y12:Y15),"n/a") -> -0.036278756
A25: Peer median - Crop-nutrition peers | D25: =IFERROR(MEDIAN(D16:D19),"n/a") -> 9.4218322 | E25: =IFERROR(MEDIAN(E16:E19),"n/a") -> 16.529846 | F25: =IFERROR(MEDIAN(F16:F19),"n/a") -> 0.029705638 | G25: =IFERROR(MEDIAN(G16:G19),"n/a") -> 0.17514409 | H25: =IFERROR(MEDIAN(H16:H19),"n/a") -> 0.25630413 | I25: =IFERROR(MEDIAN(I16:I19),"n/a") -> 0.2180772 | J25: =IFERROR(MEDIAN(J16:J19),"n/a") -> 0.14055029 | K25: =IFERROR(MEDIAN(K16:K19),"n/a") -> 0.099496016 | ... Y25: =IFERROR(MEDIAN(Y16:Y19),"n/a") -> 1.0746795
A27: Anchor (Syngenta AG (global CP + Seeds)) minus all-peer median | D27: =IFERROR(D8-D21,"n/a") -> 11.869668 | E27: =IFERROR(E8-E21,"n/a") -> 21.665604 | F27: =IFERROR(F8-F21,"n/a") -> -0.03109551 | G27: =IFERROR(G8-G21,"n/a") -> -0.25585962 | H27: =IFERROR(H8-H21,"n/a") -> 0.13889559 | I27: =IFERROR(I8-I21,"n/a") -> -0.064101431 | J27: =IFERROR(J8-J21,"n/a") -> -0.039694188 | K27: =IFERROR(K8-K21,"n/a") -> -0.083894864 | ... Y27: =IFERROR(Y8-Y21,"n/a") -> -0.18313515

Sheet Rubber
A1: Rubber & tyres - Pirelli / Aeolus vs global and Chinese tyre peers and a natural-rubber producer
A2: Sinochem's rubber & tyre exposure is held through the ChemChina line (China National Tire & Rubber): Pirelli (Sinochem holds ~34.1% via Marco Polo International Italy; Pirelli's accounts state no entity controls it) and Aeolus Tyre.
A3: FY2025, ratios computed from the 'Data' sheet. Amber rows = Sinochem Holdings group entities. Peer statistics exclude Sinochem entities. 'n.m.' = not meaningful (negative EBITDA); 'n/a' = not available.
D5: Scale | F5: Growth | H5: Profitability | L5: Returns | P5: Leverage & liquidity | U5: Cash generation
A6: Entity | B6: Group | C6: Ccy | D6: Revenue (USD bn) | E6: Total assets (USD bn) | F6: Revenue growth FY25 | G6: EBITDA growth FY25 | H6: Gross margin | I6: EBITDA margin | J6: EBIT margin | K6: Net margin | L6: EBITDA / avg assets | M6: ROE (NI / avg equity) | N6: ROA (NI / avg assets) | O6: Asset turnover (x) | P6: Liabilities / assets | Q6: Debt / equity | R6: Net debt / EBITDA (x) | S6: Interest cover (EBIT / interest, x) | T6: Current ratio (x) | U6: OCF / revenue | V6: OCF / EBITDA (cash conversion) | W6: Capex / revenue | X6: FCF margin | Y6: Free cash flow (USD bn)
A7: Direction (+1 higher is better, -1 lower is better, 0 informational) | D7: 0 | E7: 0 | F7: 1 | G7: 1 | H7: 1 | I7: 1 | J7: 1 | K7: 1 | L7: 1 | M7: 1 | N7: 1 | O7: 1 | P7: -1 | Q7: -1 | R7: -1 | S7: 1 | T7: 1 | U7: 1 | V7: 1 | W7: 0 | X7: 1 | Y7: 1
